Workbook

Sheet Config
A1: Config — cost model & capital assumptions
A2: Edit BLUE / yellow-filled cells only. Every other sheet reads from here.
A3: CAPITAL & PERIOD
A4: Deployed capital (₹) | B4: 1000000 | C4: MTF capital base. Sizing is capital/4 if n<=4 else capital/n.
A5: Tracking start date | B5: 46235 | C5: Day 1 of the Daily PnL calendar. Change it and every dated sheet re-bases.
A6: Trading days per year | B6: 252 | C6: Annualisation factor for Sharpe.
A7: Risk-free rate (annual) | B7: 0.065 | C7: Sharpe numerator.
A8: MTF funded fraction of position | B8: 0.75 | C8: Portion the broker funds and charges interest on. 0.75 = you post 25% margin.
A10: COST MODEL — per product
A11: Seeded with typical Indian equity rates. VERIFY EVERY NUMBER against a real Dhan contract note before trusting the net column — statutory rates change and broker plans differ.
A12: Product | B12: Brokerage % (per order) | C12: Brokerage cap (₹/order) | D12: STT % on buy | E12: STT % on sell | F12: Exch txn % (per side) | G12: SEBI % (per side) | H12: Stamp duty % (buy side) | I12: GST % on charges | J12: DP charge (₹ per sell) | K12: MTF interest (% p.a.)
A13: MTF | B13: 0.0003 | C13: 20 | D13: 0.001 | E13: 0.001 | F13: 2.97e-05 | G13: 1e-06 | H13: 0.00015 | I13: 0.18 | J13: 15.34 | K13: 0.15
A14: CNC | B14: 0 | C14: 0 | D14: 0.001 | E14: 0.001 | F14: 2.97e-05 | G14: 1e-06 | H14: 0.00015 | I14: 0.18 | J14: 15.34 | K14: 0
A15: INTRADAY | B15: 0.0003 | C15: 20 | D15: 0 | E15: 0.00025 | F15: 2.97e-05 | G15: 1e-06 | H15: 3e-05 | I15: 0.18 | J15: 0 | K15: 0
A17: ASSUMPTIONS BAKED INTO THE COST FORMULAS
A18: 1. Brokerage = MIN(cap, pct x order value), charged on BOTH entry and exit orders. Set cap huge if your plan is pure-percentage.
A19: 2. STT on delivery (MTF/CNC) hits both legs; on INTRADAY it is sell-side only. A short's 'sell' is its ENTRY — the formula handles that.
A20: 3. Stamp duty is buy-side only. For a short, the buy is the COVER.
A21: 4. GST applies to brokerage + exchange txn + SEBI fees. Not to STT or stamp duty.
A22: 5. MTF interest = rate/365 x holding days x entry value x funded fraction (B8). Real MTF interest varies by scrip margin, so this is an approximation.
A23: 6. DP/demat charge is added once per closed trade on delivery products; ₹0 on INTRADAY, so short legs are unaffected.
A24: 7. Slippage is NOT a modelled cost — it is measured directly as (fill price vs 15:20 reference price) in the Trade Log.
A26: HOW TO USE THE TRADE LOG
A27: Type only into BLUE columns: Trade ID, Signal Date, Symbol, Leg, Product, Ref Price, Entry Date, Entry Price, Qty, Exit Date, Exit Stage, Exit Price, Last Price, Broker Actual Net, Notes.
A28: Everything else is a formula. Do not overwrite it.
A29: ONE ROW PER LEG. A long that gets shorted on exit is two rows. Use the same Trade ID stem with -L and -S suffixes — the Signal ID column strips the suffix and pairs them automatically.
... A33: Grey columns at the far right are internal cost-lookup helpers. Ignore them, don't delete them.

Sheet Summary
A1: Key P&L statistics — gross and net
A2: Fully derived from the Trade Log and Daily PnL. Nothing on this sheet is typed by hand.
A3: PERIOD & CAPITAL
A4: Deployed capital | B4: =Config!$B$4 -> 1000000
A5: First entry date | B5: =IFERROR(MIN('Trade Log'!$H$4:$H$503),"") -> 46251
A6: Last exit date | B6: =IFERROR(MAX('Trade Log'!$L$4:$L$503),"") -> 46252
A7: Calendar days elapsed | B7: =IF(OR($B$5="",$B$6=""),"",$B$6-$B$5+1) -> 2
A8: Active trading days | B8: =COUNTIFS('Daily PnL'!$C$4:$C$403,">0") -> 1 | G8: Days on which at least one leg closed.
A10: HEADLINE P&L
A11: Gross P&L | B11: =SUM('Trade Log'!$Q$4:$Q$503) -> 24775.5
A12: Total costs | B12: =SUM('Trade Log'!$Y$4:$Y$503) -> 856.94781
A13: Net P&L | B13: =SUM('Trade Log'!$Z$4:$Z$503) -> 23918.552 | G13: The anchor number for the whole workbook.
A14: Gross return on capital | B14: =IF(Config!$B$4=0,"",$B$11/Config!$B$4) -> 0.0247755
A15: Net return on capital | B15: =IF(Config!$B$4=0,"",$B$13/Config!$B$4) -> 0.023918552
A16: Cost drag (% of gross) | B16: =IF($B$11=0,"",$B$12/$B$11) -> 0.034588517 | G16: How much of the gross edge the cost model eats.
A17: Total turnover (both sides) | B17: =SUM('Trade Log'!$K$4:$K$503)+SUM('Trade Log'!$O$4:$O$503) -> 1052896.5
A18: Costs as bp of turnover | B18: =IF($B$17=0,"",$B$12/$B$17*10000) -> 8.1389558 | G18: Compare against your ~25bp/side assumption.
A19: Annualised net return (CAGR-style) | B19: =IF(OR($B$7="",$B$7<=0,Config!$B$4=0),"",$B$13/Config!$B$4*365/$B$7) -> 4.3651358 | G19: Simple scaling, not compounded. Meaningless until you have a few months of data.
A21: SPLIT BY LEG
B22: Gross P&L | C22: Total Costs | D22: Net P&L | E22: Legs | F22: Net / Leg | G22: Win Rate
A23: LONG | B23: =SUMIF('Trade Log'!$E$4:$E$503,$A23,'Trade Log'!$Q$4:$Q$503) -> 19546.5 | C23: =SUMIF('Trade Log'!$E$4:$E$503,$A23,'Trade Log'!$Y$4:$Y$503) -> 715.13719 | D23: =SUMIF('Trade Log'!$E$4:$E$503,$A23,'Trade Log'!$Z$4:$Z$503) -> 18831.363 | E23: =COUNTIFS('Trade Log'!$E$4:$E$503,$A23,'Trade Log'!$Z$4:$Z$503,"<>") -> 1 | F23: =IF($E23=0,"",$D23/$E23) -> 18831.363 | G23: =IF($E23=0,"",COUNTIFS('Trade Log'!$E$4:$E$503,$A23,'Trade Log'!$Z$4:$Z$503,">0")/$E23) -> 1
A24: SHORT | B24: =SUMIF('Trade Log'!$E$4:$E$503,$A24,'Trade Log'!$Q$4:$Q$503) -> 5229 | C24: =SUMIF('Trade Log'!$E$4:$E$503,$A24,'Trade Log'!$Y$4:$Y$503) -> 141.81062 | D24: =SUMIF('Trade Log'!$E$4:$E$503,$A24,'Trade Log'!$Z$4:$Z$503) -> 5087.1894 | E24: =COUNTIFS('Trade Log'!$E$4:$E$503,$A24,'Trade Log'!$Z$4:$Z$503,"<>") -> 1 | F24: =IF($E24=0,"",$D24/$E24) -> 5087.1894 | G24: =IF($E24=0,"",COUNTIFS('Trade Log'!$E$4:$E$503,$A24,'Trade Log'!$Z$4:$Z$503,">0")/$E24) -> 1
A25: TOTAL | B25: =SUM(B23:B24) -> 24775.5 | C25: =SUM(C23:C24) -> 856.94781 | D25: =SUM(D23:D24) -> 23918.552 | E25: =SUM(E23:E24) -> 2 | F25: =IF($E$25=0,"",$D$25/$E$25) -> 11959.276
A26: If the SHORT row is net-negative, the short-on-exit overlay is not paying for itself once real fills and INTRADAY costs are applied.
A28: FULL-CYCLE (SIGNAL-LEVEL) RESULTS
A29: One signal = the long plus its paired short overlay leg, matched on Signal ID. This is the number that actually reflects a day's decision.
A30: Signals completed | B30: =COUNT('Trade Log'!$AF$4:$AF$503) -> 1
A31: Total cycle net P&L | B31: =SUM('Trade Log'!$AF$4:$AF$503) -> 23918.552
A32: Average net per signal | B32: =IFERROR($B$31/$B$30,"") -> 23918.552
A33: Cycle win rate | B33: =IFERROR(COUNTIF('Trade Log'!$AF$4:$AF$503,">0")/$B$30,"") -> 1
A34: Best signal | B34: =IFERROR(MAX('Trade Log'!$AF$4:$AF$503),"") -> 23918.552
A35: Worst signal | B35: =IFERROR(MIN('Trade Log'!$AF$4:$AF$503),"") -> 23918.552
A36: Cycle profit factor | B36: =IFERROR(SUMIF('Trade Log'!$AF$4:$AF$503,">0")/ABS(SUMIF('Trade Log'!$AF$4:$AF$503,"<0")),"")
A38: COST BREAKDOWN
A39: Component | B39: Total (₹) | C39: bp of Turnover | D39: % of All Costs
A40: Brokerage | B40: =SUM('Trade Log'!$S$4:$S$503) -> 80 | C40: =IF($B$17=0,"",$B40/$B$17*10000) -> 0.75980878 | D40: =IF($B$12=0,"",$B40/$B$12) -> 0.093354576
A41: STT | B41: =SUM('Trade Log'!$T$4:$T$503) -> 586.644 | C41: =IF($B$17=0,"",$B41/$B$17*10000) -> 5.5717157 | D41: =IF($B$12=0,"",$B41/$B$12) -> 0.68457378
A42: Exchange txn | B42: =SUM('Trade Log'!$U$4:$U$503) -> 31.271026 | C42: =IF($B$17=0,"",$B42/$B$17*10000) -> 0.297 | D42: =IF($B$12=0,"",$B42/$B$12) -> 0.036491167
A43: SEBI + Stamp + DP | B43: =SUM('Trade Log'!$V$4:$V$503) -> 61.799292 | C43: =IF($B$17=0,"",$B43/$B$17*10000) -> 0.58694555 | D43: =IF($B$12=0,"",$B43/$B$12) -> 0.072115584
A44: GST | B44: =SUM('Trade Log'!$W$4:$W$503) -> 20.218306 | C44: =IF($B$17=0,"",$B44/$B$17*10000) -> 0.19202558 | D44: =IF($B$12=0,"",$B44/$B$12) -> 0.023593392
...

Sheet Trade Log
A1: Trade Log — one row per leg
A2: BLUE header = you type it. Dark header = formula. Grey header = internal helper.
A3: Trade ID | B3: Signal ID | C3: Signal Date | D3: Symbol | E3: Leg | F3: Product | G3: Ref Price | H3: Entry Date | I3: Entry Price | J3: Qty | K3: Entry Value | L3: Exit Date | M3: Exit Stage | N3: Exit Price | O3: Exit Value | P3: Holding Days | Q3: Gross P&L | R3: Gross Ret % | S3: Brokerage | T3: STT | U3: Exch Txn | V3: SEBI+Stamp+DP | W3: GST | X3: MTF Interest | Y3: Total Costs | Z3: Net P&L | AA3: Net Ret % | AB3: Cost (bp) | AC3: Entry Slip (bp) | AD3: Last Price | AE3: Unrealised Gross | AF3: Cycle Net (L+S) | AG3: Cycle Ret % | AH3: Broker Actual Net | AI3: Model - Broker | AJ3: Notes | AK3: hlp:prod | AL3: hlp:buy | AM3: hlp:sell
A4: 2026-08-17-TVSSRICHAK-L | B4: =IF($D4="","",IF(OR(RIGHT($A4,2)="-L",RIGHT($A4,2)="-S"),LEFT($A4,LEN($A4)-2),$A4)) -> 2026-08-17-TVSSRICHAK | C4: 46251 | D4: TVSSRICHAK | E4: LONG | F4: MTF | G4: 100 | H4: 46251 | I4: 100.35 | J4: 2490 | K4: =IF($D4="","",$I4*$J4) -> 249871.5 | L4: 46252 | M4: EXIT_925 | N4: 108.2 | O4: =IF(OR($D4="",$N4=""),"",$N4*$J4) -> 269418 | P4: =IF(OR($D4="",$L4=""),"",MAX($L4-$H4,0)) -> 1 | Q4: =IF(OR($D4="",$N4=""),"",IF($E4="LONG",($N4-$I4)*$J4,($I4-$N4)*$J4)) -> 19546.5 | R4: =IF(OR($D4="",$Q4="",$K4=0),"",$Q4/$K4) -> 0.078226208 | S4: =IF(OR($D4="",$N4=""),"",MIN(INDEX(Config!$C$13:$C$15,$AK4),INDEX(Config!$B$13:$B$15,$AK4)*$K4)+MIN(INDEX(Config!$C$13:$C$15,$AK4),INDEX(Config!$B$13:$B$15,$AK4)*$O4)) -> 40 | T4: =IF(OR($D4="",$N4=""),"",INDEX(Config!$D$13:$D$15,$AK4)*$AL4+INDEX(Config!$E$13:$E$15,$AK4)*$AM4) -> 519.2895 | U4: =IF(OR($D4="",$N4=""),"",INDEX(Config!$F$13:$F$15,$AK4)*($K4+$O4)) -> 15.422898 | V4: =IF(OR($D4="",$N4=""),"",INDEX(Config!$G$13:$G$15,$AK4)*($K4+$O4)+INDEX(Config!$H$13:$H$15,$AK4)*$AL4+INDEX(Config!$J$13:$J$15,$AK4)) -> 53.340015 | W4: =IF(OR($D4="",$N4=""),"",INDEX(Config!$I$13:$I$15,$AK4)*($S4+$U4+INDEX(Config!$G$13:$G$15,$AK4)*($K4+$O4))) -> 10.069594 | X4: =IF(OR($D4="",$N4=""),"",INDEX(Config!$K$13:$K$15,$AK4)/365*$P4*$K4*Config!$B$8) -> 77.015188 | Y4: =IF(OR($D4="",$N4=""),"",SUM($S4:$X4)) -> 715.13719 | Z4: =IF(OR($D4="",$Q4=""),"",$Q4-$Y4) -> 18831.363 | AA4: =IF(OR($D4="",$Z4="",$K4=0),"",$Z4/$K4) -> 0.075364188 | AB4: =IF(OR($D4="",$Y4="",$K4=0),"",$Y4/$K4*10000) -> 28.620199 | AC4: =IF(OR($D4="",$G4="",$G4=0,$I4=""),"",IF($E4="LONG",($I4-$G4)/$G4,($G4-$I4)/$G4)*10000) -> 35 | AE4: =IF(OR($D4="",$N4<>"",$AD4=""),"",IF($E4="LONG",($AD4-$I4)*$J4,($I4-$AD4)*$J4)) | AF4: =IF(OR($D4="",$E4<>"LONG",$Z4=""),"",$Z4+SUMIFS($Z$4:$Z$503,$B$4:$B$503,$B4,$E$4:$E$503,"SHORT")) -> 23918.552 | AG4: =IF(OR($AF4="",$K4=0),"",$AF4/$K4) -> 0.095723411 | AI4: =IF(OR($D4="",$AH4="",$Z4=""),"",$Z4-$AH4) | AJ4: EXAMPLE — delete. Entered 15:21, exited profitably at 9:25. | AK4: =IF($D4="","",IFERROR(MATCH($F4,Config!$A$13:$A$15,0),1)) -> 1 | AL4: =IF(OR($D4="",$N4=""),"",IF($E4="LONG",$K4,$O4)) -> 249871.5 | AM4: =IF(OR($D4="",$N4=""),"",IF($E4="LONG",$O4,$K4)) -> 269418
A5: 2026-08-17-TVSSRICHAK-S | B5: =IF($D5="","",IF(OR(RIGHT($A5,2)="-L",RIGHT($A5,2)="-S"),LEFT($A5,LEN($A5)-2),$A5)) -> 2026-08-17-TVSSRICHAK | C5: 46251 | D5: TVSSRICHAK | E5: SHORT | F5: INTRADAY | G5: 108.2 | H5: 46252 | I5: 108.2 | J5: 2490 | K5: =IF($D5="","",$I5*$J5) -> 269418 | L5: 46252 | M5: SQUAREOFF_239 | N5: 106.1 | O5: =IF(OR($D5="",$N5=""),"",$N5*$J5) -> 264189 | P5: =IF(OR($D5="",$L5=""),"",MAX($L5-$H5,0)) -> 0 | Q5: =IF(OR($D5="",$N5=""),"",IF($E5="LONG",($N5-$I5)*$J5,($I5-$N5)*$J5)) -> 5229 | R5: =IF(OR($D5="",$Q5="",$K5=0),"",$Q5/$K5) -> 0.019408503 | S5: =IF(OR($D5="",$N5=""),"",MIN(INDEX(Config!$C$13:$C$15,$AK5),INDEX(Config!$B$13:$B$15,$AK5)*$K5)+MIN(INDEX(Config!$C$13:$C$15,$AK5),INDEX(Config!$B$13:$B$15,$AK5)*$O5)) -> 40 | T5: =IF(OR($D5="",$N5=""),"",INDEX(Config!$D$13:$D$15,$AK5)*$AL5+INDEX(Config!$E$13:$E$15,$AK5)*$AM5) -> 67.3545 | U5: =IF(OR($D5="",$N5=""),"",INDEX(Config!$F$13:$F$15,$AK5)*($K5+$O5)) -> 15.848128 | V5: =IF(OR($D5="",$N5=""),"",INDEX(Config!$G$13:$G$15,$AK5)*($K5+$O5)+INDEX(Config!$H$13:$H$15,$AK5)*$AL5+INDEX(Config!$J$13:$J$15,$AK5)) -> 8.459277 | W5: =IF(OR($D5="",$N5=""),"",INDEX(Config!$I$13:$I$15,$AK5)*($S5+$U5+INDEX(Config!$G$13:$G$15,$AK5)*($K5+$O5))) -> 10.148712 | X5: =IF(OR($D5="",$N5=""),"",INDEX(Config!$K$13:$K$15,$AK5)/365*$P5*$K5*Config!$B$8) -> 0 | Y5: =IF(OR($D5="",$N5=""),"",SUM($S5:$X5)) -> 141.81062 | Z5: =IF(OR($D5="",$Q5=""),"",$Q5-$Y5) -> 5087.1894 | AA5: =IF(OR($D5="",$Z5="",$K5=0),"",$Z5/$K5) -> 0.018882144 | AB5: =IF(OR($D5="",$Y5="",$K5=0),"",$Y5/$K5*10000) -> 5.263591 | AC5: =IF(OR($D5="",$G5="",$G5=0,$I5=""),"",IF($E5="LONG",($I5-$G5)/$G5,($G5-$I5)/$G5)*10000) -> 0 | AE5: =IF(OR($D5="",$N5<>"",$AD5=""),"",IF($E5="LONG",($AD5-$I5)*$J5,($I5-$AD5)*$J5)) | AF5: =IF(OR($D5="",$E5<>"LONG",$Z5=""),"",$Z5+SUMIFS($Z$4:$Z$503,$B$4:$B$503,$B5,$E$4:$E$503,"SHORT")) | AG5: =IF(OR($AF5="",$K5=0),"",$AF5/$K5) | AI5: =IF(OR($D5="",$AH5="",$Z5=""),"",$Z5-$AH5) | AJ5: EXAMPLE — delete. Short-on-exit overlay, covered at 2:39pm. | AK5: =IF($D5="","",IFERROR(MATCH($F5,Config!$A$13:$A$15,0),1)) -> 3 | AL5: =IF(OR($D5="",$N5=""),"",IF($E5="LONG",$K5,$O5)) -> 264189 | AM5: =IF(OR($D5="",$N5=""),"",IF($E5="LONG",$O5,$K5)) -> 269418
B6: =IF($D6="","",IF(OR(RIGHT($A6,2)="-L",RIGHT($A6,2)="-S"),LEFT($A6,LEN($A6)-2),$A6)) | K6: =IF($D6="","",$I6*$J6) | O6: =IF(OR($D6="",$N6=""),"",$N6*$J6) | P6: =IF(OR($D6="",$L6=""),"",MAX($L6-$H6,0)) | Q6: =IF(OR($D6="",$N6=""),"",IF($E6="LONG",($N6-$I6)*$J6,($I6-$N6)*$J6)) | R6: =IF(OR($D6="",$Q6="",$K6=0),"",$Q6/$K6) | S6: =IF(OR($D6="",$N6=""),"",MIN(INDEX(Config!$C$13:$C$15,$AK6),INDEX(Config!$B$13:$B$15,$AK6)*$K6)+MIN(INDEX(Config!$C$13:$C$15,$AK6),INDEX(Config!$B$13:$B$15,$AK6)*$O6)) | T6: =IF(OR($D6="",$N6=""),"",INDEX(Config!$D$13:$D$15,$AK6)*$AL6+INDEX(Config!$E$13:$E$15,$AK6)*$AM6) | U6: =IF(OR($D6="",$N6=""),"",INDEX(Config!$F$13:$F$15,$AK6)*($K6+$O6)) | V6: =IF(OR($D6="",$N6=""),"",INDEX(Config!$G$13:$G$15,$AK6)*($K6+$O6)+INDEX(Config!$H$13:$H$15,$AK6)*$AL6+INDEX(Config!$J$13:$J$15,$AK6)) | W6: =IF(OR($D6="",$N6=""),"",INDEX(Config!$I$13:$I$15,$AK6)*($S6+$U6+INDEX(Config!$G$13:$G$15,$AK6)*($K6+$O6))) | X6: =IF(OR($D6="",$N6=""),"",INDEX(Config!$K$13:$K$15,$AK6)/365*$P6*$K6*Config!$B$8) | Y6: =IF(OR($D6="",$N6=""),"",SUM($S6:$X6)) | Z6: =IF(OR($D6="",$Q6=""),"",$Q6-$Y6) | AA6: =IF(OR($D6="",$Z6="",$K6=0),"",$Z6/$K6) | AB6: =IF(OR($D6="",$Y6="",$K6=0),"",$Y6/$K6*10000) | AC6: =IF(OR($D6="",$G6="",$G6=0,$I6=""),"",IF($E6="LONG",($I6-$G6)/$G6,($G6-$I6)/$G6)*10000) | AE6: =IF(OR($D6="",$N6<>"",$AD6=""),"",IF($E6="LONG",($AD6-$I6)*$J6,($I6-$AD6)*$J6)) | AF6: =IF(OR($D6="",$E6<>"LONG",$Z6=""),"",$Z6+SUMIFS($Z$4:$Z$503,$B$4:$B$503,$B6,$E$4:$E$503,"SHORT")) | AG6: =IF(OR($AF6="",$K6=0),"",$AF6/$K6) | AI6: =IF(OR($D6="",$AH6="",$Z6=""),"",$Z6-$AH6) | AK6: =IF($D6="","",IFERROR(MATCH($F6,Config!$A$13:$A$15,0),1)) | AL6: =IF(OR($D6="",$N6=""),"",IF($E6="LONG",$K6,$O6)) | AM6: =IF(OR($D6="",$N6=""),"",IF($E6="LONG",$O6,$K6))
B7: =IF($D7="","",IF(OR(RIGHT($A7,2)="-L",RIGHT($A7,2)="-S"),LEFT($A7,LEN($A7)-2),$A7)) | K7: =IF($D7="","",$I7*$J7) | O7: =IF(OR($D7="",$N7=""),"",$N7*$J7) | P7: =IF(OR($D7="",$L7=""),"",MAX($L7-$H7,0)) | Q7: =IF(OR($D7="",$N7=""),"",IF($E7="LONG",($N7-$I7)*$J7,($I7-$N7)*$J7)) | R7: =IF(OR($D7="",$Q7="",$K7=0),"",$Q7/$K7) | S7: =IF(OR($D7="",$N7=""),"",MIN(INDEX(Config!$C$13:$C$15,$AK7),INDEX(Config!$B$13:$B$15,$AK7)*$K7)+MIN(INDEX(Config!$C$13:$C$15,$AK7),INDEX(Config!$B$13:$B$15,$AK7)*$O7)) | T7: =IF(OR($D7="",$N7=""),"",INDEX(Config!$D$13:$D$15,$AK7)*$AL7+INDEX(Config!$E$13:$E$15,$AK7)*$AM7) | U7: =IF(OR($D7="",$N7=""),"",INDEX(Config!$F$13:$F$15,$AK7)*($K7+$O7)) | V7: =IF(OR($D7="",$N7=""),"",INDEX(Config!$G$13:$G$15,$AK7)*($K7+$O7)+INDEX(Config!$H$13:$H$15,$AK7)*$AL7+INDEX(Config!$J$13:$J$15,$AK7)) | W7: =IF(OR($D7="",$N7=""),"",INDEX(Config!$I$13:$I$15,$AK7)*($S7+$U7+INDEX(Config!$G$13:$G$15,$AK7)*($K7+$O7))) | X7: =IF(OR($D7="",$N7=""),"",INDEX(Config!$K$13:$K$15,$AK7)/365*$P7*$K7*Config!$B$8) | Y7: =IF(OR($D7="",$N7=""),"",SUM($S7:$X7)) | Z7: =IF(OR($D7="",$Q7=""),"",$Q7-$Y7) | AA7: =IF(OR($D7="",$Z7="",$K7=0),"",$Z7/$K7) | AB7: =IF(OR($D7="",$Y7="",$K7=0),"",$Y7/$K7*10000) | AC7: =IF(OR($D7="",$G7="",$G7=0,$I7=""),"",IF($E7="LONG",($I7-$G7)/$G7,($G7-$I7)/$G7)*10000) | AE7: =IF(OR($D7="",$N7<>"",$AD7=""),"",IF($E7="LONG",($AD7-$I7)*$J7,($I7-$AD7)*$J7)) | AF7: =IF(OR($D7="",$E7<>"LONG",$Z7=""),"",$Z7+SUMIFS($Z$4:$Z$503,$B$4:$B$503,$B7,$E$4:$E$503,"SHORT")) | AG7: =IF(OR($AF7="",$K7=0),"",$AF7/$K7) | AI7: =IF(OR($D7="",$AH7="",$Z7=""),"",$Z7-$AH7) | AK7: =IF($D7="","",IFERROR(MATCH($F7,Config!$A$13:$A$15,0),1)) | AL7: =IF(OR($D7="",$N7=""),"",IF($E7="LONG",$K7,$O7)) | AM7: =IF(OR($D7="",$N7=""),"",IF($E7="LONG",$O7,$K7))
B8: =IF($D8="","",IF(OR(RIGHT($A8,2)="-L",RIGHT($A8,2)="-S"),LEFT($A8,LEN($A8)-2),$A8)) | K8: =IF($D8="","",$I8*$J8) | O8: =IF(OR($D8="",$N8=""),"",$N8*$J8) | P8: =IF(OR($D8="",$L8=""),"",MAX($L8-$H8,0)) | Q8: =IF(OR($D8="",$N8=""),"",IF($E8="LONG",($N8-$I8)*$J8,($I8-$N8)*$J8)) | R8: =IF(OR($D8="",$Q8="",$K8=0),"",$Q8/$K8) | S8: =IF(OR($D8="",$N8=""),"",MIN(INDEX(Config!$C$13:$C$15,$AK8),INDEX(Config!$B$13:$B$15,$AK8)*$K8)+MIN(INDEX(Config!$C$13:$C$15,$AK8),INDEX(Config!$B$13:$B$15,$AK8)*$O8)) | T8: =IF(OR($D8="",$N8=""),"",INDEX(Config!$D$13:$D$15,$AK8)*$AL8+INDEX(Config!$E$13:$E$15,$AK8)*$AM8) | U8: =IF(OR($D8="",$N8=""),"",INDEX(Config!$F$13:$F$15,$AK8)*($K8+$O8)) | V8: =IF(OR($D8="",$N8=""),"",INDEX(Config!$G$13:$G$15,$AK8)*($K8+$O8)+INDEX(Config!$H$13:$H$15,$AK8)*$AL8+INDEX(Config!$J$13:$J$15,$AK8)) | W8: =IF(OR($D8="",$N8=""),"",INDEX(Config!$I$13:$I$15,$AK8)*($S8+$U8+INDEX(Config!$G$13:$G$15,$AK8)*($K8+$O8))) | X8: =IF(OR($D8="",$N8=""),"",INDEX(Config!$K$13:$K$15,$AK8)/365*$P8*$K8*Config!$B$8) | Y8: =IF(OR($D8="",$N8=""),"",SUM($S8:$X8)) | Z8: =IF(OR($D8="",$Q8=""),"",$Q8-$Y8) | AA8: =IF(OR($D8="",$Z8="",$K8=0),"",$Z8/$K8) | AB8: =IF(OR($D8="",$Y8="",$K8=0),"",$Y8/$K8*10000) | AC8: =IF(OR($D8="",$G8="",$G8=0,$I8=""),"",IF($E8="LONG",($I8-$G8)/$G8,($G8-$I8)/$G8)*10000) | AE8: =IF(OR($D8="",$N8<>"",$AD8=""),"",IF($E8="LONG",($AD8-$I8)*$J8,($I8-$AD8)*$J8)) | AF8: =IF(OR($D8="",$E8<>"LONG",$Z8=""),"",$Z8+SUMIFS($Z$4:$Z$503,$B$4:$B$503,$B8,$E$4:$E$503,"SHORT")) | AG8: =IF(OR($AF8="",$K8=0),"",$AF8/$K8) | AI8: =IF(OR($D8="",$AH8="",$Z8=""),"",$Z8-$AH8) | AK8: =IF($D8="","",IFERROR(MATCH($F8,Config!$A$13:$A$15,0),1)) | AL8: =IF(OR($D8="",$N8=""),"",IF($E8="LONG",$K8,$O8)) | AM8: =IF(OR($D8="",$N8=""),"",IF($E8="LONG",$O8,$K8))
B9: =IF($D9="","",IF(OR(RIGHT($A9,2)="-L",RIGHT($A9,2)="-S"),LEFT($A9,LEN($A9)-2),$A9)) | K9: =IF($D9="","",$I9*$J9) | O9: =IF(OR($D9="",$N9=""),"",$N9*$J9) | P9: =IF(OR($D9="",$L9=""),"",MAX($L9-$H9,0)) | Q9: =IF(OR($D9="",$N9=""),"",IF($E9="LONG",($N9-$I9)*$J9,($I9-$N9)*$J9)) | R9: =IF(OR($D9="",$Q9="",$K9=0),"",$Q9/$K9) | S9: =IF(OR($D9="",$N9=""),"",MIN(INDEX(Config!$C$13:$C$15,$AK9),INDEX(Config!$B$13:$B$15,$AK9)*$K9)+MIN(INDEX(Config!$C$13:$C$15,$AK9),INDEX(Config!$B$13:$B$15,$AK9)*$O9)) | T9: =IF(OR($D9="",$N9=""),"",INDEX(Config!$D$13:$D$15,$AK9)*$AL9+INDEX(Config!$E$13:$E$15,$AK9)*$AM9) | U9: =IF(OR($D9="",$N9=""),"",INDEX(Config!$F$13:$F$15,$AK9)*($K9+$O9)) | V9: =IF(OR($D9="",$N9=""),"",INDEX(Config!$G$13:$G$15,$AK9)*($K9+$O9)+INDEX(Config!$H$13:$H$15,$AK9)*$AL9+INDEX(Config!$J$13:$J$15,$AK9)) | W9: =IF(OR($D9="",$N9=""),"",INDEX(Config!$I$13:$I$15,$AK9)*($S9+$U9+INDEX(Config!$G$13:$G$15,$AK9)*($K9+$O9))) | X9: =IF(OR($D9="",$N9=""),"",INDEX(Config!$K$13:$K$15,$AK9)/365*$P9*$K9*Config!$B$8) | Y9: =IF(OR($D9="",$N9=""),"",SUM($S9:$X9)) | Z9: =IF(OR($D9="",$Q9=""),"",$Q9-$Y9) | AA9: =IF(OR($D9="",$Z9="",$K9=0),"",$Z9/$K9) | AB9: =IF(OR($D9="",$Y9="",$K9=0),"",$Y9/$K9*10000) | AC9: =IF(OR($D9="",$G9="",$G9=0,$I9=""),"",IF($E9="LONG",($I9-$G9)/$G9,($G9-$I9)/$G9)*10000) | AE9: =IF(OR($D9="",$N9<>"",$AD9=""),"",IF($E9="LONG",($AD9-$I9)*$J9,($I9-$AD9)*$J9)) | AF9: =IF(OR($D9="",$E9<>"LONG",$Z9=""),"",$Z9+SUMIFS($Z$4:$Z$503,$B$4:$B$503,$B9,$E$4:$E$503,"SHORT")) | AG9: =IF(OR($AF9="",$K9=0),"",$AF9/$K9) | AI9: =IF(OR($D9="",$AH9="",$Z9=""),"",$Z9-$AH9) | AK9: =IF($D9="","",IFERROR(MATCH($F9,Config!$A$13:$A$15,0),1)) | AL9: =IF(OR($D9="",$N9=""),"",IF($E9="LONG",$K9,$O9)) | AM9: =IF(OR($D9="",$N9=""),"",IF($E9="LONG",$O9,$K9))
B10: =IF($D10="","",IF(OR(RIGHT($A10,2)="-L",RIGHT($A10,2)="-S"),LEFT($A10,LEN($A10)-2),$A10)) | K10: =IF($D10="","",$I10*$J10) | O10: =IF(OR($D10="",$N10=""),"",$N10*$J10) | P10: =IF(OR($D10="",$L10=""),"",MAX($L10-$H10,0)) | Q10: =IF(OR($D10="",$N10=""),"",IF($E10="LONG",($N10-$I10)*$J10,($I10-$N10)*$J10)) | R10: =IF(OR($D10="",$Q10="",$K10=0),"",$Q10/$K10) | S10: =IF(OR($D10="",$N10=""),"",MIN(INDEX(Config!$C$13:$C$15,$AK10),INDEX(Config!$B$13:$B$15,$AK10)*$K10)+MIN(INDEX(Config!$C$13:$C$15,$AK10),INDEX(Config!$B$13:$B$15,$AK10)*$O10)) | T10: =IF(OR($D10="",$N10=""),"",INDEX(Config!$D$13:$D$15,$AK10)*$AL10+INDEX(Config!$E$13:$E$15,$AK10)*$AM10) | U10: =IF(OR($D10="",$N10=""),"",INDEX(Config!$F$13:$F$15,$AK10)*($K10+$O10)) | V10: =IF(OR($D10="",$N10=""),"",INDEX(Config!$G$13:$G$15,$AK10)*($K10+$O10)+INDEX(Config!$H$13:$H$15,$AK10)*$AL10+INDEX(Config!$J$13:$J$15,$AK10)) | W10: =IF(OR($D10="",$N10=""),"",INDEX(Config!$I$13:$I$15,$AK10)*($S10+$U10+INDEX(Config!$G$13:$G$15,$AK10)*($K10+$O10))) | X10: =IF(OR($D10="",$N10=""),"",INDEX(Config!$K$13:$K$15,$AK10)/365*$P10*$K10*Config!$B$8) | Y10: =IF(OR($D10="",$N10=""),"",SUM($S10:$X10)) | Z10: =IF(OR($D10="",$Q10=""),"",$Q10-$Y10) | AA10: =IF(OR($D10="",$Z10="",$K10=0),"",$Z10/$K10) | AB10: =IF(OR($D10="",$Y10="",$K10=0),"",$Y10/$K10*10000) | AC10: =IF(OR($D10="",$G10="",$G10=0,$I10=""),"",IF($E10="LONG",($I10-$G10)/$G10,($G10-$I10)/$G10)*10000) | AE10: =IF(OR($D10="",$N10<>"",$AD10=""),"",IF($E10="LONG",($AD10-$I10)*$J10,($I10-$AD10)*$J10)) | AF10: =IF(OR($D10="",$E10<>"LONG",$Z10=""),"",$Z10+SUMIFS($Z$4:$Z$503,$B$4:$B$503,$B10,$E$4:$E$503,"SHORT")) | AG10: =IF(OR($AF10="",$K10=0),"",$AF10/$K10) | AI10: =IF(OR($D10="",$AH10="",$Z10=""),"",$Z10-$AH10) | AK10: =IF($D10="","",IFERROR(MATCH($F10,Config!$A$13:$A$15,0),1)) | AL10: =IF(OR($D10="",$N10=""),"",IF($E10="LONG",$K10,$O10)) | AM10: =IF(OR($D10="",$N10=""),"",IF($E10="LONG",$O10,$K10))
B11: =IF($D11="","",IF(OR(RIGHT($A11,2)="-L",RIGHT($A11,2)="-S"),LEFT($A11,LEN($A11)-2),$A11)) | K11: =IF($D11="","",$I11*$J11) | O11: =IF(OR($D11="",$N11=""),"",$N11*$J11) | P11: =IF(OR($D11="",$L11=""),"",MAX($L11-$H11,0)) | Q11: =IF(OR($D11="",$N11=""),"",IF($E11="LONG",($N11-$I11)*$J11,($I11-$N11)*$J11)) | R11: =IF(OR($D11="",$Q11="",$K11=0),"",$Q11/$K11) | S11: =IF(OR($D11="",$N11=""),"",MIN(INDEX(Config!$C$13:$C$15,$AK11),INDEX(Config!$B$13:$B$15,$AK11)*$K11)+MIN(INDEX(Config!$C$13:$C$15,$AK11),INDEX(Config!$B$13:$B$15,$AK11)*$O11)) | T11: =IF(OR($D11="",$N11=""),"",INDEX(Config!$D$13:$D$15,$AK11)*$AL11+INDEX(Config!$E$13:$E$15,$AK11)*$AM11) | U11: =IF(OR($D11="",$N11=""),"",INDEX(Config!$F$13:$F$15,$AK11)*($K11+$O11)) | V11: =IF(OR($D11="",$N11=""),"",INDEX(Config!$G$13:$G$15,$AK11)*($K11+$O11)+INDEX(Config!$H$13:$H$15,$AK11)*$AL11+INDEX(Config!$J$13:$J$15,$AK11)) | W11: =IF(OR($D11="",$N11=""),"",INDEX(Config!$I$13:$I$15,$AK11)*($S11+$U11+INDEX(Config!$G$13:$G$15,$AK11)*($K11+$O11))) | X11: =IF(OR($D11="",$N11=""),"",INDEX(Config!$K$13:$K$15,$AK11)/365*$P11*$K11*Config!$B$8) | Y11: =IF(OR($D11="",$N11=""),"",SUM($S11:$X11)) | Z11: =IF(OR($D11="",$Q11=""),"",$Q11-$Y11) | AA11: =IF(OR($D11="",$Z11="",$K11=0),"",$Z11/$K11) | AB11: =IF(OR($D11="",$Y11="",$K11=0),"",$Y11/$K11*10000) | AC11: =IF(OR($D11="",$G11="",$G11=0,$I11=""),"",IF($E11="LONG",($I11-$G11)/$G11,($G11-$I11)/$G11)*10000) | AE11: =IF(OR($D11="",$N11<>"",$AD11=""),"",IF($E11="LONG",($AD11-$I11)*$J11,($I11-$AD11)*$J11)) | AF11: =IF(OR($D11="",$E11<>"LONG",$Z11=""),"",$Z11+SUMIFS($Z$4:$Z$503,$B$4:$B$503,$B11,$E$4:$E$503,"SHORT")) | AG11: =IF(OR($AF11="",$K11=0),"",$AF11/$K11) | AI11: =IF(OR($D11="",$AH11="",$Z11=""),"",$Z11-$AH11) | AK11: =IF($D11="","",IFERROR(MATCH($F11,Config!$A$13:$A$15,0),1)) | AL11: =IF(OR($D11="",$N11=""),"",IF($E11="LONG",$K11,$O11)) | AM11: =IF(OR($D11="",$N11=""),"",IF($E11="LONG",$O11,$K11))
B12: =IF($D12="","",IF(OR(RIGHT($A12,2)="-L",RIGHT($A12,2)="-S"),LEFT($A12,LEN($A12)-2),$A12)) | K12: =IF($D12="","",$I12*$J12) | O12: =IF(OR($D12="",$N12=""),"",$N12*$J12) | P12: =IF(OR($D12="",$L12=""),"",MAX($L12-$H12,0)) | Q12: =IF(OR($D12="",$N12=""),"",IF($E12="LONG",($N12-$I12)*$J12,($I12-$N12)*$J12)) | R12: =IF(OR($D12="",$Q12="",$K12=0),"",$Q12/$K12) | S12: =IF(OR($D12="",$N12=""),"",MIN(INDEX(Config!$C$13:$C$15,$AK12),INDEX(Config!$B$13:$B$15,$AK12)*$K12)+MIN(INDEX(Config!$C$13:$C$15,$AK12),INDEX(Config!$B$13:$B$15,$AK12)*$O12)) | T12: =IF(OR($D12="",$N12=""),"",INDEX(Config!$D$13:$D$15,$AK12)*$AL12+INDEX(Config!$E$13:$E$15,$AK12)*$AM12) | U12: =IF(OR($D12="",$N12=""),"",INDEX(Config!$F$13:$F$15,$AK12)*($K12+$O12)) | V12: =IF(OR($D12="",$N12=""),"",INDEX(Config!$G$13:$G$15,$AK12)*($K12+$O12)+INDEX(Config!$H$13:$H$15,$AK12)*$AL12+INDEX(Config!$J$13:$J$15,$AK12)) | W12: =IF(OR($D12="",$N12=""),"",INDEX(Config!$I$13:$I$15,$AK12)*($S12+$U12+INDEX(Config!$G$13:$G$15,$AK12)*($K12+$O12))) | X12: =IF(OR($D12="",$N12=""),"",INDEX(Config!$K$13:$K$15,$AK12)/365*$P12*$K12*Config!$B$8) | Y12: =IF(OR($D12="",$N12=""),"",SUM($S12:$X12)) | Z12: =IF(OR($D12="",$Q12=""),"",$Q12-$Y12) | AA12: =IF(OR($D12="",$Z12="",$K12=0),"",$Z12/$K12) | AB12: =IF(OR($D12="",$Y12="",$K12=0),"",$Y12/$K12*10000) | AC12: =IF(OR($D12="",$G12="",$G12=0,$I12=""),"",IF($E12="LONG",($I12-$G12)/$G12,($G12-$I12)/$G12)*10000) | AE12: =IF(OR($D12="",$N12<>"",$AD12=""),"",IF($E12="LONG",($AD12-$I12)*$J12,($I12-$AD12)*$J12)) | AF12: =IF(OR($D12="",$E12<>"LONG",$Z12=""),"",$Z12+SUMIFS($Z$4:$Z$503,$B$4:$B$503,$B12,$E$4:$E$503,"SHORT")) | AG12: =IF(OR($AF12="",$K12=0),"",$AF12/$K12) | AI12: =IF(OR($D12="",$AH12="",$Z12=""),"",$Z12-$AH12) | AK12: =IF($D12="","",IFERROR(MATCH($F12,Config!$A$13:$A$15,0),1)) | AL12: =IF(OR($D12="",$N12=""),"",IF($E12="LONG",$K12,$O12)) | AM12: =IF(OR($D12="",$N12=""),"",IF($E12="LONG",$O12,$K12))
B13: =IF($D13="","",IF(OR(RIGHT($A13,2)="-L",RIGHT($A13,2)="-S"),LEFT($A13,LEN($A13)-2),$A13)) | K13: =IF($D13="","",$I13*$J13) | O13: =IF(OR($D13="",$N13=""),"",$N13*$J13) | P13: =IF(OR($D13="",$L13=""),"",MAX($L13-$H13,0)) | Q13: =IF(OR($D13="",$N13=""),"",IF($E13="LONG",($N13-$I13)*$J13,($I13-$N13)*$J13)) | R13: =IF(OR($D13="",$Q13="",$K13=0),"",$Q13/$K13) | S13: =IF(OR($D13="",$N13=""),"",MIN(INDEX(Config!$C$13:$C$15,$AK13),INDEX(Config!$B$13:$B$15,$AK13)*$K13)+MIN(INDEX(Config!$C$13:$C$15,$AK13),INDEX(Config!$B$13:$B$15,$AK13)*$O13)) | T13: =IF(OR($D13="",$N13=""),"",INDEX(Config!$D$13:$D$15,$AK13)*$AL13+INDEX(Config!$E$13:$E$15,$AK13)*$AM13) | U13: =IF(OR($D13="",$N13=""),"",INDEX(Config!$F$13:$F$15,$AK13)*($K13+$O13)) | V13: =IF(OR($D13="",$N13=""),"",INDEX(Config!$G$13:$G$15,$AK13)*($K13+$O13)+INDEX(Config!$H$13:$H$15,$AK13)*$AL13+INDEX(Config!$J$13:$J$15,$AK13)) | W13: =IF(OR($D13="",$N13=""),"",INDEX(Config!$I$13:$I$15,$AK13)*($S13+$U13+INDEX(Config!$G$13:$G$15,$AK13)*($K13+$O13))) | X13: =IF(OR($D13="",$N13=""),"",INDEX(Config!$K$13:$K$15,$AK13)/365*$P13*$K13*Config!$B$8) | Y13: =IF(OR($D13="",$N13=""),"",SUM($S13:$X13)) | Z13: =IF(OR($D13="",$Q13=""),"",$Q13-$Y13) | AA13: =IF(OR($D13="",$Z13="",$K13=0),"",$Z13/$K13) | AB13: =IF(OR($D13="",$Y13="",$K13=0),"",$Y13/$K13*10000) | AC13: =IF(OR($D13="",$G13="",$G13=0,$I13=""),"",IF($E13="LONG",($I13-$G13)/$G13,($G13-$I13)/$G13)*10000) | AE13: =IF(OR($D13="",$N13<>"",$AD13=""),"",IF($E13="LONG",($AD13-$I13)*$J13,($I13-$AD13)*$J13)) | AF13: =IF(OR($D13="",$E13<>"LONG",$Z13=""),"",$Z13+SUMIFS($Z$4:$Z$503,$B$4:$B$503,$B13,$E$4:$E$503,"SHORT")) | AG13: =IF(OR($AF13="",$K13=0),"",$AF13/$K13) | AI13: =IF(OR($D13="",$AH13="",$Z13=""),"",$Z13-$AH13) | AK13: =IF($D13="","",IFERROR(MATCH($F13,Config!$A$13:$A$15,0),1)) | AL13: =IF(OR($D13="",$N13=""),"",IF($E13="LONG",$K13,$O13)) | AM13: =IF(OR($D13="",$N13=""),"",IF($E13="LONG",$O13,$K13))
B14: =IF($D14="","",IF(OR(RIGHT($A14,2)="-L",RIGHT($A14,2)="-S"),LEFT($A14,LEN($A14)-2),$A14)) | K14: =IF($D14="","",$I14*$J14) | O14: =IF(OR($D14="",$N14=""),"",$N14*$J14) | P14: =IF(OR($D14="",$L14=""),"",MAX($L14-$H14,0)) | Q14: =IF(OR($D14="",$N14=""),"",IF($E14="LONG",($N14-$I14)*$J14,($I14-$N14)*$J14)) | R14: =IF(OR($D14="",$Q14="",$K14=0),"",$Q14/$K14) | S14: =IF(OR($D14="",$N14=""),"",MIN(INDEX(Config!$C$13:$C$15,$AK14),INDEX(Config!$B$13:$B$15,$AK14)*$K14)+MIN(INDEX(Config!$C$13:$C$15,$AK14),INDEX(Config!$B$13:$B$15,$AK14)*$O14)) | T14: =IF(OR($D14="",$N14=""),"",INDEX(Config!$D$13:$D$15,$AK14)*$AL14+INDEX(Config!$E$13:$E$15,$AK14)*$AM14) | U14: =IF(OR($D14="",$N14=""),"",INDEX(Config!$F$13:$F$15,$AK14)*($K14+$O14)) | V14: =IF(OR($D14="",$N14=""),"",INDEX(Config!$G$13:$G$15,$AK14)*($K14+$O14)+INDEX(Config!$H$13:$H$15,$AK14)*$AL14+INDEX(Config!$J$13:$J$15,$AK14)) | W14: =IF(OR($D14="",$N14=""),"",INDEX(Config!$I$13:$I$15,$AK14)*($S14+$U14+INDEX(Config!$G$13:$G$15,$AK14)*($K14+$O14))) | X14: =IF(OR($D14="",$N14=""),"",INDEX(Config!$K$13:$K$15,$AK14)/365*$P14*$K14*Config!$B$8) | Y14: =IF(OR($D14="",$N14=""),"",SUM($S14:$X14)) | Z14: =IF(OR($D14="",$Q14=""),"",$Q14-$Y14) | AA14: =IF(OR($D14="",$Z14="",$K14=0),"",$Z14/$K14) | AB14: =IF(OR($D14="",$Y14="",$K14=0),"",$Y14/$K14*10000) | AC14: =IF(OR($D14="",$G14="",$G14=0,$I14=""),"",IF($E14="LONG",($I14-$G14)/$G14,($G14-$I14)/$G14)*10000) | AE14: =IF(OR($D14="",$N14<>"",$AD14=""),"",IF($E14="LONG",($AD14-$I14)*$J14,($I14-$AD14)*$J14)) | AF14: =IF(OR($D14="",$E14<>"LONG",$Z14=""),"",$Z14+SUMIFS($Z$4:$Z$503,$B$4:$B$503,$B14,$E$4:$E$503,"SHORT")) | AG14: =IF(OR($AF14="",$K14=0),"",$AF14/$K14) | AI14: =IF(OR($D14="",$AH14="",$Z14=""),"",$Z14-$AH14) | AK14: =IF($D14="","",IFERROR(MATCH($F14,Config!$A$13:$A$15,0),1)) | AL14: =IF(OR($D14="",$N14=""),"",IF($E14="LONG",$K14,$O14)) | AM14: =IF(OR($D14="",$N14=""),"",IF($E14="LONG",$O14,$K14))
B15: =IF($D15="","",IF(OR(RIGHT($A15,2)="-L",RIGHT($A15,2)="-S"),LEFT($A15,LEN($A15)-2),$A15)) | K15: =IF($D15="","",$I15*$J15) | O15: =IF(OR($D15="",$N15=""),"",$N15*$J15) | P15: =IF(OR($D15="",$L15=""),"",MAX($L15-$H15,0)) | Q15: =IF(OR($D15="",$N15=""),"",IF($E15="LONG",($N15-$I15)*$J15,($I15-$N15)*$J15)) | R15: =IF(OR($D15="",$Q15="",$K15=0),"",$Q15/$K15) | S15: =IF(OR($D15="",$N15=""),"",MIN(INDEX(Config!$C$13:$C$15,$AK15),INDEX(Config!$B$13:$B$15,$AK15)*$K15)+MIN(INDEX(Config!$C$13:$C$15,$AK15),INDEX(Config!$B$13:$B$15,$AK15)*$O15)) | T15: =IF(OR($D15="",$N15=""),"",INDEX(Config!$D$13:$D$15,$AK15)*$AL15+INDEX(Config!$E$13:$E$15,$AK15)*$AM15) | U15: =IF(OR($D15="",$N15=""),"",INDEX(Config!$F$13:$F$15,$AK15)*($K15+$O15)) | V15: =IF(OR($D15="",$N15=""),"",INDEX(Config!$G$13:$G$15,$AK15)*($K15+$O15)+INDEX(Config!$H$13:$H$15,$AK15)*$AL15+INDEX(Config!$J$13:$J$15,$AK15)) | W15: =IF(OR($D15="",$N15=""),"",INDEX(Config!$I$13:$I$15,$AK15)*($S15+$U15+INDEX(Config!$G$13:$G$15,$AK15)*($K15+$O15))) | X15: =IF(OR($D15="",$N15=""),"",INDEX(Config!$K$13:$K$15,$AK15)/365*$P15*$K15*Config!$B$8) | Y15: =IF(OR($D15="",$N15=""),"",SUM($S15:$X15)) | Z15: =IF(OR($D15="",$Q15=""),"",$Q15-$Y15) | AA15: =IF(OR($D15="",$Z15="",$K15=0),"",$Z15/$K15) | AB15: =IF(OR($D15="",$Y15="",$K15=0),"",$Y15/$K15*10000) | AC15: =IF(OR($D15="",$G15="",$G15=0,$I15=""),"",IF($E15="LONG",($I15-$G15)/$G15,($G15-$I15)/$G15)*10000) | AE15: =IF(OR($D15="",$N15<>"",$AD15=""),"",IF($E15="LONG",($AD15-$I15)*$J15,($I15-$AD15)*$J15)) | AF15: =IF(OR($D15="",$E15<>"LONG",$Z15=""),"",$Z15+SUMIFS($Z$4:$Z$503,$B$4:$B$503,$B15,$E$4:$E$503,"SHORT")) | AG15: =IF(OR($AF15="",$K15=0),"",$AF15/$K15) | AI15: =IF(OR($D15="",$AH15="",$Z15=""),"",$Z15-$AH15) | AK15: =IF($D15="","",IFERROR(MATCH($F15,Config!$A$13:$A$15,0),1)) | AL15: =IF(OR($D15="",$N15=""),"",IF($E15="LONG",$K15,$O15)) | AM15: =IF(OR($D15="",$N15=""),"",IF($E15="LONG",$O15,$K15))
B16: =IF($D16="","",IF(OR(RIGHT($A16,2)="-L",RIGHT($A16,2)="-S"),LEFT($A16,LEN($A16)-2),$A16)) | K16: =IF($D16="","",$I16*$J16) | O16: =IF(OR($D16="",$N16=""),"",$N16*$J16) | P16: =IF(OR($D16="",$L16=""),"",MAX($L16-$H16,0)) | Q16: =IF(OR($D16="",$N16=""),"",IF($E16="LONG",($N16-$I16)*$J16,($I16-$N16)*$J16)) | R16: =IF(OR($D16="",$Q16="",$K16=0),"",$Q16/$K16) | S16: =IF(OR($D16="",$N16=""),"",MIN(INDEX(Config!$C$13:$C$15,$AK16),INDEX(Config!$B$13:$B$15,$AK16)*$K16)+MIN(INDEX(Config!$C$13:$C$15,$AK16),INDEX(Config!$B$13:$B$15,$AK16)*$O16)) | T16: =IF(OR($D16="",$N16=""),"",INDEX(Config!$D$13:$D$15,$AK16)*$AL16+INDEX(Config!$E$13:$E$15,$AK16)*$AM16) | U16: =IF(OR($D16="",$N16=""),"",INDEX(Config!$F$13:$F$15,$AK16)*($K16+$O16)) | V16: =IF(OR($D16="",$N16=""),"",INDEX(Config!$G$13:$G$15,$AK16)*($K16+$O16)+INDEX(Config!$H$13:$H$15,$AK16)*$AL16+INDEX(Config!$J$13:$J$15,$AK16)) | W16: =IF(OR($D16="",$N16=""),"",INDEX(Config!$I$13:$I$15,$AK16)*($S16+$U16+INDEX(Config!$G$13:$G$15,$AK16)*($K16+$O16))) | X16: =IF(OR($D16="",$N16=""),"",INDEX(Config!$K$13:$K$15,$AK16)/365*$P16*$K16*Config!$B$8) | Y16: =IF(OR($D16="",$N16=""),"",SUM($S16:$X16)) | Z16: =IF(OR($D16="",$Q16=""),"",$Q16-$Y16) | AA16: =IF(OR($D16="",$Z16="",$K16=0),"",$Z16/$K16) | AB16: =IF(OR($D16="",$Y16="",$K16=0),"",$Y16/$K16*10000) | AC16: =IF(OR($D16="",$G16="",$G16=0,$I16=""),"",IF($E16="LONG",($I16-$G16)/$G16,($G16-$I16)/$G16)*10000) | AE16: =IF(OR($D16="",$N16<>"",$AD16=""),"",IF($E16="LONG",($AD16-$I16)*$J16,($I16-$AD16)*$J16)) | AF16: =IF(OR($D16="",$E16<>"LONG",$Z16=""),"",$Z16+SUMIFS($Z$4:$Z$503,$B$4:$B$503,$B16,$E$4:$E$503,"SHORT")) | AG16: =IF(OR($AF16="",$K16=0),"",$AF16/$K16) | AI16: =IF(OR($D16="",$AH16="",$Z16=""),"",$Z16-$AH16) | AK16: =IF($D16="","",IFERROR(MATCH($F16,Config!$A$13:$A$15,0),1)) | AL16: =IF(OR($D16="",$N16=""),"",IF($E16="LONG",$K16,$O16)) | AM16: =IF(OR($D16="",$N16=""),"",IF($E16="LONG",$O16,$K16))
B17: =IF($D17="","",IF(OR(RIGHT($A17,2)="-L",RIGHT($A17,2)="-S"),LEFT($A17,LEN($A17)-2),$A17)) | K17: =IF($D17="","",$I17*$J17) | O17: =IF(OR($D17="",$N17=""),"",$N17*$J17) | P17: =IF(OR($D17="",$L17=""),"",MAX($L17-$H17,0)) | Q17: =IF(OR($D17="",$N17=""),"",IF($E17="LONG",($N17-$I17)*$J17,($I17-$N17)*$J17)) | R17: =IF(OR($D17="",$Q17="",$K17=0),"",$Q17/$K17) | S17: =IF(OR($D17="",$N17=""),"",MIN(INDEX(Config!$C$13:$C$15,$AK17),INDEX(Config!$B$13:$B$15,$AK17)*$K17)+MIN(INDEX(Config!$C$13:$C$15,$AK17),INDEX(Config!$B$13:$B$15,$AK17)*$O17)) | T17: =IF(OR($D17="",$N17=""),"",INDEX(Config!$D$13:$D$15,$AK17)*$AL17+INDEX(Config!$E$13:$E$15,$AK17)*$AM17) | U17: =IF(OR($D17="",$N17=""),"",INDEX(Config!$F$13:$F$15,$AK17)*($K17+$O17)) | V17: =IF(OR($D17="",$N17=""),"",INDEX(Config!$G$13:$G$15,$AK17)*($K17+$O17)+INDEX(Config!$H$13:$H$15,$AK17)*$AL17+INDEX(Config!$J$13:$J$15,$AK17)) | W17: =IF(OR($D17="",$N17=""),"",INDEX(Config!$I$13:$I$15,$AK17)*($S17+$U17+INDEX(Config!$G$13:$G$15,$AK17)*($K17+$O17))) | X17: =IF(OR($D17="",$N17=""),"",INDEX(Config!$K$13:$K$15,$AK17)/365*$P17*$K17*Config!$B$8) | Y17: =IF(OR($D17="",$N17=""),"",SUM($S17:$X17)) | Z17: =IF(OR($D17="",$Q17=""),"",$Q17-$Y17) | AA17: =IF(OR($D17="",$Z17="",$K17=0),"",$Z17/$K17) | AB17: =IF(OR($D17="",$Y17="",$K17=0),"",$Y17/$K17*10000) | AC17: =IF(OR($D17="",$G17="",$G17=0,$I17=""),"",IF($E17="LONG",($I17-$G17)/$G17,($G17-$I17)/$G17)*10000) | AE17: =IF(OR($D17="",$N17<>"",$AD17=""),"",IF($E17="LONG",($AD17-$I17)*$J17,($I17-$AD17)*$J17)) | AF17: =IF(OR($D17="",$E17<>"LONG",$Z17=""),"",$Z17+SUMIFS($Z$4:$Z$503,$B$4:$B$503,$B17,$E$4:$E$503,"SHORT")) | AG17: =IF(OR($AF17="",$K17=0),"",$AF17/$K17) | AI17: =IF(OR($D17="",$AH17="",$Z17=""),"",$Z17-$AH17) | AK17: =IF($D17="","",IFERROR(MATCH($F17,Config!$A$13:$A$15,0),1)) | AL17: =IF(OR($D17="",$N17=""),"",IF($E17="LONG",$K17,$O17)) | AM17: =IF(OR($D17="",$N17=""),"",IF($E17="LONG",$O17,$K17))
... B503: =IF($D503="","",IF(OR(RIGHT($A503,2)="-L",RIGHT($A503,2)="-S"),LEFT($A503,LEN($A503)-2),$A503)) | K503: =IF($D503="","",$I503*$J503) | O503: =IF(OR($D503="",$N503=""),"",$N503*$J503) | P503: =IF(OR($D503="",$L503=""),"",MAX($L503-$H503,0)) | Q503: =IF(OR($D503="",$N503=""),"",IF($E503="LONG",($N503-$I503)*$J503,($I503-$N503)*$J503)) | R503: =IF(OR($D503="",$Q503="",$K503=0),"",$Q503/$K503) | S503: =IF(OR($D503="",$N503=""),"",MIN(INDEX(Config!$C$13:$C$15,$AK503),INDEX(Config!$B$13:$B$15,$AK503)*$K503)+MIN(INDEX(Config!$C$13:$C$15,$AK503),INDEX(Config!$B$13:$B$15,$AK503)*$O503)) | T503: =IF(OR($D503="",$N503=""),"",INDEX(Config!$D$13:$D$15,$AK503)*$AL503+INDEX(Config!$E$13:$E$15,$AK503)*$AM503) | U503: =IF(OR($D503="",$N503=""),"",INDEX(Config!$F$13:$F$15,$AK503)*($K503+$O503)) | V503: =IF(OR($D503="",$N503=""),"",INDEX(Config!$G$13:$G$15,$AK503)*($K503+$O503)+INDEX(Config!$H$13:$H$15,$AK503)*$AL503+INDEX(Config!$J$13:$J$15,$AK503)) | W503: =IF(OR($D503="",$N503=""),"",INDEX(Config!$I$13:$I$15,$AK503)*($S503+$U503+INDEX(Config!$G$13:$G$15,$AK503)*($K503+$O503))) | X503: =IF(OR($D503="",$N503=""),"",INDEX(Config!$K$13:$K$15,$AK503)/365*$P503*$K503*Config!$B$8) | Y503: =IF(OR($D503="",$N503=""),"",SUM($S503:$X503)) | Z503: =IF(OR($D503="",$Q503=""),"",$Q503-$Y503) | AA503: =IF(OR($D503="",$Z503="",$K503=0),"",$Z503/$K503) | AB503: =IF(OR($D503="",$Y503="",$K503=0),"",$Y503/$K503*10000) | AC503: =IF(OR($D503="",$G503="",$G503=0,$I503=""),"",IF($E503="LONG",($I503-$G503)/$G503,($G503-$I503)/$G503)*10000) | AE503: =IF(OR($D503="",$N503<>"",$AD503=""),"",IF($E503="LONG",($AD503-$I503)*$J503,($I503-$AD503)*$J503)) | AF503: =IF(OR($D503="",$E503<>"LONG",$Z503=""),"",$Z503+SUMIFS($Z$4:$Z$503,$B$4:$B$503,$B503,$E$4:$E$503,"SHORT")) | AG503: =IF(OR($AF503="",$K503=0),"",$AF503/$K503) | AI503: =IF(OR($D503="",$AH503="",$Z503=""),"",$Z503-$AH503) | AK503: =IF($D503="","",IFERROR(MATCH($F503,Config!$A$13:$A$15,0),1)) | AL503: =IF(OR($D503="",$N503=""),"",IF($E503="LONG",$K503,$O503)) | AM503: =IF(OR($D503="",$N503=""),"",IF($E503="LONG",$O503,$K503))

Sheet Daily PnL
A1: Daily P&L, equity curve, drawdown & rolling risk
A2: P&L is attributed to the EXIT date. Calendar starts at Config!B5. Blank Net = no trades closed that day.
A3: Date | B3: Day | C3: Legs Closed | D3: Long Gross | E3: Short Gross | F3: Total Gross | G3: Total Costs | H3: Net P&L | I3: Cumulative Net | J3: Equity | K3: Peak Equity | L3: Drawdown (₹) | M3: Drawdown % | N3: Capital Deployed | O3: Daily Ret | P3: Roll 20d Net | Q3: Roll 20d Sharpe | R3: Roll 60d Sharpe | S3: hlp:winstk | T3: hlp:losstk
A4: =Config!$B$5 -> 46235 | B4: =IF($A4="","",TEXT($A4,"ddd")) -> Sat | C4: =IF($A4="","",COUNTIFS('Trade Log'!$L$4:$L$503,$A4)) -> 0 | D4: =IF($A4="","",SUMIFS('Trade Log'!$Q$4:$Q$503,'Trade Log'!$L$4:$L$503,$A4,'Trade Log'!$E$4:$E$503,"LONG")) -> 0 | E4: =IF($A4="","",SUMIFS('Trade Log'!$Q$4:$Q$503,'Trade Log'!$L$4:$L$503,$A4,'Trade Log'!$E$4:$E$503,"SHORT")) -> 0 | F4: =IF($A4="","",$D4+$E4) -> 0 | G4: =IF($A4="","",SUMIFS('Trade Log'!$Y$4:$Y$503,'Trade Log'!$L$4:$L$503,$A4)) -> 0 | H4: =IF($A4="","",IF($C4=0,"",$F4-$G4)) | I4: =IF($A4="","",0+IF($H4="",0,$H4)) -> 0 | J4: =IF($A4="","",Config!$B$4+$I4) -> 1000000 | K4: =IF($A4="","",MAX($J$4:$J4)) -> 1000000 | L4: =IF($A4="","",$J4-$K4) -> 0 | M4: =IF(OR($A4="",$K4=0),"",$L4/$K4) -> 0 | N4: =IF($A4="","",SUMIFS('Trade Log'!$K$4:$K$503,'Trade Log'!$H$4:$H$503,$A4)) -> 0 | O4: =IF(OR($A4="",$H4="",Config!$B$4=0),"",$H4/Config!$B$4) | P4: =IF($A4="","",SUM($H$4:$H4)) -> 0 | Q4: =IF($A4="","",IFERROR((AVERAGE($O$4:$O4)-Config!$B$7/Config!$B$6)/STDEV($O$4:$O4)*SQRT(Config!$B$6),"")) | R4: =IF($A4="","",IFERROR((AVERAGE($O$4:$O4)-Config!$B$7/Config!$B$6)/STDEV($O$4:$O4)*SQRT(Config!$B$6),"")) | S4: =IF($H4="",0,IF($H4>0,1,0)) -> 0 | T4: =IF($H4="",0,IF($H4<0,1,0)) -> 0
A5: =IF($A4="","",$A4+1) -> 46236 | B5: =IF($A5="","",TEXT($A5,"ddd")) -> Sun | C5: =IF($A5="","",COUNTIFS('Trade Log'!$L$4:$L$503,$A5)) -> 0 | D5: =IF($A5="","",SUMIFS('Trade Log'!$Q$4:$Q$503,'Trade Log'!$L$4:$L$503,$A5,'Trade Log'!$E$4:$E$503,"LONG")) -> 0 | E5: =IF($A5="","",SUMIFS('Trade Log'!$Q$4:$Q$503,'Trade Log'!$L$4:$L$503,$A5,'Trade Log'!$E$4:$E$503,"SHORT")) -> 0 | F5: =IF($A5="","",$D5+$E5) -> 0 | G5: =IF($A5="","",SUMIFS('Trade Log'!$Y$4:$Y$503,'Trade Log'!$L$4:$L$503,$A5)) -> 0 | H5: =IF($A5="","",IF($C5=0,"",$F5-$G5)) | I5: =IF($A5="","",$I4+IF($H5="",0,$H5)) -> 0 | J5: =IF($A5="","",Config!$B$4+$I5) -> 1000000 | K5: =IF($A5="","",MAX($J$4:$J5)) -> 1000000 | L5: =IF($A5="","",$J5-$K5) -> 0 | M5: =IF(OR($A5="",$K5=0),"",$L5/$K5) -> 0 | N5: =IF($A5="","",SUMIFS('Trade Log'!$K$4:$K$503,'Trade Log'!$H$4:$H$503,$A5)) -> 0 | O5: =IF(OR($A5="",$H5="",Config!$B$4=0),"",$H5/Config!$B$4) | P5: =IF($A5="","",SUM($H$4:$H5)) -> 0 | Q5: =IF($A5="","",IFERROR((AVERAGE($O$4:$O5)-Config!$B$7/Config!$B$6)/STDEV($O$4:$O5)*SQRT(Config!$B$6),"")) | R5: =IF($A5="","",IFERROR((AVERAGE($O$4:$O5)-Config!$B$7/Config!$B$6)/STDEV($O$4:$O5)*SQRT(Config!$B$6),"")) | S5: =IF($H5="",$S4,IF($H5>0,$S4+1,0)) -> 0 | T5: =IF($H5="",$T4,IF($H5<0,$T4+1,0)) -> 0
A6: =IF($A5="","",$A5+1) -> 46237 | B6: =IF($A6="","",TEXT($A6,"ddd")) -> Mon | C6: =IF($A6="","",COUNTIFS('Trade Log'!$L$4:$L$503,$A6)) -> 0 | D6: =IF($A6="","",SUMIFS('Trade Log'!$Q$4:$Q$503,'Trade Log'!$L$4:$L$503,$A6,'Trade Log'!$E$4:$E$503,"LONG")) -> 0 | E6: =IF($A6="","",SUMIFS('Trade Log'!$Q$4:$Q$503,'Trade Log'!$L$4:$L$503,$A6,'Trade Log'!$E$4:$E$503,"SHORT")) -> 0 | F6: =IF($A6="","",$D6+$E6) -> 0 | G6: =IF($A6="","",SUMIFS('Trade Log'!$Y$4:$Y$503,'Trade Log'!$L$4:$L$503,$A6)) -> 0 | H6: =IF($A6="","",IF($C6=0,"",$F6-$G6)) | I6: =IF($A6="","",$I5+IF($H6="",0,$H6)) -> 0 | J6: =IF($A6="","",Config!$B$4+$I6) -> 1000000 | K6: =IF($A6="","",MAX($J$4:$J6)) -> 1000000 | L6: =IF($A6="","",$J6-$K6) -> 0 | M6: =IF(OR($A6="",$K6=0),"",$L6/$K6) -> 0 | N6: =IF($A6="","",SUMIFS('Trade Log'!$K$4:$K$503,'Trade Log'!$H$4:$H$503,$A6)) -> 0 | O6: =IF(OR($A6="",$H6="",Config!$B$4=0),"",$H6/Config!$B$4) | P6: =IF($A6="","",SUM($H$4:$H6)) -> 0 | Q6: =IF($A6="","",IFERROR((AVERAGE($O$4:$O6)-Config!$B$7/Config!$B$6)/STDEV($O$4:$O6)*SQRT(Config!$B$6),"")) | R6: =IF($A6="","",IFERROR((AVERAGE($O$4:$O6)-Config!$B$7/Config!$B$6)/STDEV($O$4:$O6)*SQRT(Config!$B$6),"")) | S6: =IF($H6="",$S5,IF($H6>0,$S5+1,0)) -> 0 | T6: =IF($H6="",$T5,IF($H6<0,$T5+1,0)) -> 0
A7: =IF($A6="","",$A6+1) -> 46238 | B7: =IF($A7="","",TEXT($A7,"ddd")) -> Tue | C7: =IF($A7="","",COUNTIFS('Trade Log'!$L$4:$L$503,$A7)) -> 0 | D7: =IF($A7="","",SUMIFS('Trade Log'!$Q$4:$Q$503,'Trade Log'!$L$4:$L$503,$A7,'Trade Log'!$E$4:$E$503,"LONG")) -> 0 | E7: =IF($A7="","",SUMIFS('Trade Log'!$Q$4:$Q$503,'Trade Log'!$L$4:$L$503,$A7,'Trade Log'!$E$4:$E$503,"SHORT")) -> 0 | F7: =IF($A7="","",$D7+$E7) -> 0 | G7: =IF($A7="","",SUMIFS('Trade Log'!$Y$4:$Y$503,'Trade Log'!$L$4:$L$503,$A7)) -> 0 | H7: =IF($A7="","",IF($C7=0,"",$F7-$G7)) | I7: =IF($A7="","",$I6+IF($H7="",0,$H7)) -> 0 | J7: =IF($A7="","",Config!$B$4+$I7) -> 1000000 | K7: =IF($A7="","",MAX($J$4:$J7)) -> 1000000 | L7: =IF($A7="","",$J7-$K7) -> 0 | M7: =IF(OR($A7="",$K7=0),"",$L7/$K7) -> 0 | N7: =IF($A7="","",SUMIFS('Trade Log'!$K$4:$K$503,'Trade Log'!$H$4:$H$503,$A7)) -> 0 | O7: =IF(OR($A7="",$H7="",Config!$B$4=0),"",$H7/Config!$B$4) | P7: =IF($A7="","",SUM($H$4:$H7)) -> 0 | Q7: =IF($A7="","",IFERROR((AVERAGE($O$4:$O7)-Config!$B$7/Config!$B$6)/STDEV($O$4:$O7)*SQRT(Config!$B$6),"")) | R7: =IF($A7="","",IFERROR((AVERAGE($O$4:$O7)-Config!$B$7/Config!$B$6)/STDEV($O$4:$O7)*SQRT(Config!$B$6),"")) | S7: =IF($H7="",$S6,IF($H7>0,$S6+1,0)) -> 0 | T7: =IF($H7="",$T6,IF($H7<0,$T6+1,0)) -> 0
A8: =IF($A7="","",$A7+1) -> 46239 | B8: =IF($A8="","",TEXT($A8,"ddd")) -> Wed | C8: =IF($A8="","",COUNTIFS('Trade Log'!$L$4:$L$503,$A8)) -> 0 | D8: =IF($A8="","",SUMIFS('Trade Log'!$Q$4:$Q$503,'Trade Log'!$L$4:$L$503,$A8,'Trade Log'!$E$4:$E$503,"LONG")) -> 0 | E8: =IF($A8="","",SUMIFS('Trade Log'!$Q$4:$Q$503,'Trade Log'!$L$4:$L$503,$A8,'Trade Log'!$E$4:$E$503,"SHORT")) -> 0 | F8: =IF($A8="","",$D8+$E8) -> 0 | G8: =IF($A8="","",SUMIFS('Trade Log'!$Y$4:$Y$503,'Trade Log'!$L$4:$L$503,$A8)) -> 0 | H8: =IF($A8="","",IF($C8=0,"",$F8-$G8)) | I8: =IF($A8="","",$I7+IF($H8="",0,$H8)) -> 0 | J8: =IF($A8="","",Config!$B$4+$I8) -> 1000000 | K8: =IF($A8="","",MAX($J$4:$J8)) -> 1000000 | L8: =IF($A8="","",$J8-$K8) -> 0 | M8: =IF(OR($A8="",$K8=0),"",$L8/$K8) -> 0 | N8: =IF($A8="","",SUMIFS('Trade Log'!$K$4:$K$503,'Trade Log'!$H$4:$H$503,$A8)) -> 0 | O8: =IF(OR($A8="",$H8="",Config!$B$4=0),"",$H8/Config!$B$4) | P8: =IF($A8="","",SUM($H$4:$H8)) -> 0 | Q8: =IF($A8="","",IFERROR((AVERAGE($O$4:$O8)-Config!$B$7/Config!$B$6)/STDEV($O$4:$O8)*SQRT(Config!$B$6),"")) | R8: =IF($A8="","",IFERROR((AVERAGE($O$4:$O8)-Config!$B$7/Config!$B$6)/STDEV($O$4:$O8)*SQRT(Config!$B$6),"")) | S8: =IF($H8="",$S7,IF($H8>0,$S7+1,0)) -> 0 | T8: =IF($H8="",$T7,IF($H8<0,$T7+1,0)) -> 0
A9: =IF($A8="","",$A8+1) -> 46240 | B9: =IF($A9="","",TEXT($A9,"ddd")) -> Thu | C9: =IF($A9="","",COUNTIFS('Trade Log'!$L$4:$L$503,$A9)) -> 0 | D9: =IF($A9="","",SUMIFS('Trade Log'!$Q$4:$Q$503,'Trade Log'!$L$4:$L$503,$A9,'Trade Log'!$E$4:$E$503,"LONG")) -> 0 | E9: =IF($A9="","",SUMIFS('Trade Log'!$Q$4:$Q$503,'Trade Log'!$L$4:$L$503,$A9,'Trade Log'!$E$4:$E$503,"SHORT")) -> 0 | F9: =IF($A9="","",$D9+$E9) -> 0 | G9: =IF($A9="","",SUMIFS('Trade Log'!$Y$4:$Y$503,'Trade Log'!$L$4:$L$503,$A9)) -> 0 | H9: =IF($A9="","",IF($C9=0,"",$F9-$G9)) | I9: =IF($A9="","",$I8+IF($H9="",0,$H9)) -> 0 | J9: =IF($A9="","",Config!$B$4+$I9) -> 1000000 | K9: =IF($A9="","",MAX($J$4:$J9)) -> 1000000 | L9: =IF($A9="","",$J9-$K9) -> 0 | M9: =IF(OR($A9="",$K9=0),"",$L9/$K9) -> 0 | N9: =IF($A9="","",SUMIFS('Trade Log'!$K$4:$K$503,'Trade Log'!$H$4:$H$503,$A9)) -> 0 | O9: =IF(OR($A9="",$H9="",Config!$B$4=0),"",$H9/Config!$B$4) | P9: =IF($A9="","",SUM($H$4:$H9)) -> 0 | Q9: =IF($A9="","",IFERROR((AVERAGE($O$4:$O9)-Config!$B$7/Config!$B$6)/STDEV($O$4:$O9)*SQRT(Config!$B$6),"")) | R9: =IF($A9="","",IFERROR((AVERAGE($O$4:$O9)-Config!$B$7/Config!$B$6)/STDEV($O$4:$O9)*SQRT(Config!$B$6),"")) | S9: =IF($H9="",$S8,IF($H9>0,$S8+1,0)) -> 0 | T9: =IF($H9="",$T8,IF($H9<0,$T8+1,0)) -> 0
A10: =IF($A9="","",$A9+1) -> 46241 | B10: =IF($A10="","",TEXT($A10,"ddd")) -> Fri | C10: =IF($A10="","",COUNTIFS('Trade Log'!$L$4:$L$503,$A10)) -> 0 | D10: =IF($A10="","",SUMIFS('Trade Log'!$Q$4:$Q$503,'Trade Log'!$L$4:$L$503,$A10,'Trade Log'!$E$4:$E$503,"LONG")) -> 0 | E10: =IF($A10="","",SUMIFS('Trade Log'!$Q$4:$Q$503,'Trade Log'!$L$4:$L$503,$A10,'Trade Log'!$E$4:$E$503,"SHORT")) -> 0 | F10: =IF($A10="","",$D10+$E10) -> 0 | G10: =IF($A10="","",SUMIFS('Trade Log'!$Y$4:$Y$503,'Trade Log'!$L$4:$L$503,$A10)) -> 0 | H10: =IF($A10="","",IF($C10=0,"",$F10-$G10)) | I10: =IF($A10="","",$I9+IF($H10="",0,$H10)) -> 0 | J10: =IF($A10="","",Config!$B$4+$I10) -> 1000000 | K10: =IF($A10="","",MAX($J$4:$J10)) -> 1000000 | L10: =IF($A10="","",$J10-$K10) -> 0 | M10: =IF(OR($A10="",$K10=0),"",$L10/$K10) -> 0 | N10: =IF($A10="","",SUMIFS('Trade Log'!$K$4:$K$503,'Trade Log'!$H$4:$H$503,$A10)) -> 0 | O10: =IF(OR($A10="",$H10="",Config!$B$4=0),"",$H10/Config!$B$4) | P10: =IF($A10="","",SUM($H$4:$H10)) -> 0 | Q10: =IF($A10="","",IFERROR((AVERAGE($O$4:$O10)-Config!$B$7/Config!$B$6)/STDEV($O$4:$O10)*SQRT(Config!$B$6),"")) | R10: =IF($A10="","",IFERROR((AVERAGE($O$4:$O10)-Config!$B$7/Config!$B$6)/STDEV($O$4:$O10)*SQRT(Config!$B$6),"")) | S10: =IF($H10="",$S9,IF($H10>0,$S9+1,0)) -> 0 | T10: =IF($H10="",$T9,IF($H10<0,$T9+1,0)) -> 0
A11: =IF($A10="","",$A10+1) -> 46242 | B11: =IF($A11="","",TEXT($A11,"ddd")) -> Sat | C11: =IF($A11="","",COUNTIFS('Trade Log'!$L$4:$L$503,$A11)) -> 0 | D11: =IF($A11="","",SUMIFS('Trade Log'!$Q$4:$Q$503,'Trade Log'!$L$4:$L$503,$A11,'Trade Log'!$E$4:$E$503,"LONG")) -> 0 | E11: =IF($A11="","",SUMIFS('Trade Log'!$Q$4:$Q$503,'Trade Log'!$L$4:$L$503,$A11,'Trade Log'!$E$4:$E$503,"SHORT")) -> 0 | F11: =IF($A11="","",$D11+$E11) -> 0 | G11: =IF($A11="","",SUMIFS('Trade Log'!$Y$4:$Y$503,'Trade Log'!$L$4:$L$503,$A11)) -> 0 | H11: =IF($A11="","",IF($C11=0,"",$F11-$G11)) | I11: =IF($A11="","",$I10+IF($H11="",0,$H11)) -> 0 | J11: =IF($A11="","",Config!$B$4+$I11) -> 1000000 | K11: =IF($A11="","",MAX($J$4:$J11)) -> 1000000 | L11: =IF($A11="","",$J11-$K11) -> 0 | M11: =IF(OR($A11="",$K11=0),"",$L11/$K11) -> 0 | N11: =IF($A11="","",SUMIFS('Trade Log'!$K$4:$K$503,'Trade Log'!$H$4:$H$503,$A11)) -> 0 | O11: =IF(OR($A11="",$H11="",Config!$B$4=0),"",$H11/Config!$B$4) | P11: =IF($A11="","",SUM($H$4:$H11)) -> 0 | Q11: =IF($A11="","",IFERROR((AVERAGE($O$4:$O11)-Config!$B$7/Config!$B$6)/STDEV($O$4:$O11)*SQRT(Config!$B$6),"")) | R11: =IF($A11="","",IFERROR((AVERAGE($O$4:$O11)-Config!$B$7/Config!$B$6)/STDEV($O$4:$O11)*SQRT(Config!$B$6),"")) | S11: =IF($H11="",$S10,IF($H11>0,$S10+1,0)) -> 0 | T11: =IF($H11="",$T10,IF($H11<0,$T10+1,0)) -> 0
A12: =IF($A11="","",$A11+1) -> 46243 | B12: =IF($A12="","",TEXT($A12,"ddd")) -> Sun | C12: =IF($A12="","",COUNTIFS('Trade Log'!$L$4:$L$503,$A12)) -> 0 | D12: =IF($A12="","",SUMIFS('Trade Log'!$Q$4:$Q$503,'Trade Log'!$L$4:$L$503,$A12,'Trade Log'!$E$4:$E$503,"LONG")) -> 0 | E12: =IF($A12="","",SUMIFS('Trade Log'!$Q$4:$Q$503,'Trade Log'!$L$4:$L$503,$A12,'Trade Log'!$E$4:$E$503,"SHORT")) -> 0 | F12: =IF($A12="","",$D12+$E12) -> 0 | G12: =IF($A12="","",SUMIFS('Trade Log'!$Y$4:$Y$503,'Trade Log'!$L$4:$L$503,$A12)) -> 0 | H12: =IF($A12="","",IF($C12=0,"",$F12-$G12)) | I12: =IF($A12="","",$I11+IF($H12="",0,$H12)) -> 0 | J12: =IF($A12="","",Config!$B$4+$I12) -> 1000000 | K12: =IF($A12="","",MAX($J$4:$J12)) -> 1000000 | L12: =IF($A12="","",$J12-$K12) -> 0 | M12: =IF(OR($A12="",$K12=0),"",$L12/$K12) -> 0 | N12: =IF($A12="","",SUMIFS('Trade Log'!$K$4:$K$503,'Trade Log'!$H$4:$H$503,$A12)) -> 0 | O12: =IF(OR($A12="",$H12="",Config!$B$4=0),"",$H12/Config!$B$4) | P12: =IF($A12="","",SUM($H$4:$H12)) -> 0 | Q12: =IF($A12="","",IFERROR((AVERAGE($O$4:$O12)-Config!$B$7/Config!$B$6)/STDEV($O$4:$O12)*SQRT(Config!$B$6),"")) | R12: =IF($A12="","",IFERROR((AVERAGE($O$4:$O12)-Config!$B$7/Config!$B$6)/STDEV($O$4:$O12)*SQRT(Config!$B$6),"")) | S12: =IF($H12="",$S11,IF($H12>0,$S11+1,0)) -> 0 | T12: =IF($H12="",$T11,IF($H12<0,$T11+1,0)) -> 0
A13: =IF($A12="","",$A12+1) -> 46244 | B13: =IF($A13="","",TEXT($A13,"ddd")) -> Mon | C13: =IF($A13="","",COUNTIFS('Trade Log'!$L$4:$L$503,$A13)) -> 0 | D13: =IF($A13="","",SUMIFS('Trade Log'!$Q$4:$Q$503,'Trade Log'!$L$4:$L$503,$A13,'Trade Log'!$E$4:$E$503,"LONG")) -> 0 | E13: =IF($A13="","",SUMIFS('Trade Log'!$Q$4:$Q$503,'Trade Log'!$L$4:$L$503,$A13,'Trade Log'!$E$4:$E$503,"SHORT")) -> 0 | F13: =IF($A13="","",$D13+$E13) -> 0 | G13: =IF($A13="","",SUMIFS('Trade Log'!$Y$4:$Y$503,'Trade Log'!$L$4:$L$503,$A13)) -> 0 | H13: =IF($A13="","",IF($C13=0,"",$F13-$G13)) | I13: =IF($A13="","",$I12+IF($H13="",0,$H13)) -> 0 | J13: =IF($A13="","",Config!$B$4+$I13) -> 1000000 | K13: =IF($A13="","",MAX($J$4:$J13)) -> 1000000 | L13: =IF($A13="","",$J13-$K13) -> 0 | M13: =IF(OR($A13="",$K13=0),"",$L13/$K13) -> 0 | N13: =IF($A13="","",SUMIFS('Trade Log'!$K$4:$K$503,'Trade Log'!$H$4:$H$503,$A13)) -> 0 | O13: =IF(OR($A13="",$H13="",Config!$B$4=0),"",$H13/Config!$B$4) | P13: =IF($A13="","",SUM($H$4:$H13)) -> 0 | Q13: =IF($A13="","",IFERROR((AVERAGE($O$4:$O13)-Config!$B$7/Config!$B$6)/STDEV($O$4:$O13)*SQRT(Config!$B$6),"")) | R13: =IF($A13="","",IFERROR((AVERAGE($O$4:$O13)-Config!$B$7/Config!$B$6)/STDEV($O$4:$O13)*SQRT(Config!$B$6),"")) | S13: =IF($H13="",$S12,IF($H13>0,$S12+1,0)) -> 0 | T13: =IF($H13="",$T12,IF($H13<0,$T12+1,0)) -> 0
A14: =IF($A13="","",$A13+1) -> 46245 | B14: =IF($A14="","",TEXT($A14,"ddd")) -> Tue | C14: =IF($A14="","",COUNTIFS('Trade Log'!$L$4:$L$503,$A14)) -> 0 | D14: =IF($A14="","",SUMIFS('Trade Log'!$Q$4:$Q$503,'Trade Log'!$L$4:$L$503,$A14,'Trade Log'!$E$4:$E$503,"LONG")) -> 0 | E14: =IF($A14="","",SUMIFS('Trade Log'!$Q$4:$Q$503,'Trade Log'!$L$4:$L$503,$A14,'Trade Log'!$E$4:$E$503,"SHORT")) -> 0 | F14: =IF($A14="","",$D14+$E14) -> 0 | G14: =IF($A14="","",SUMIFS('Trade Log'!$Y$4:$Y$503,'Trade Log'!$L$4:$L$503,$A14)) -> 0 | H14: =IF($A14="","",IF($C14=0,"",$F14-$G14)) | I14: =IF($A14="","",$I13+IF($H14="",0,$H14)) -> 0 | J14: =IF($A14="","",Config!$B$4+$I14) -> 1000000 | K14: =IF($A14="","",MAX($J$4:$J14)) -> 1000000 | L14: =IF($A14="","",$J14-$K14) -> 0 | M14: =IF(OR($A14="",$K14=0),"",$L14/$K14) -> 0 | N14: =IF($A14="","",SUMIFS('Trade Log'!$K$4:$K$503,'Trade Log'!$H$4:$H$503,$A14)) -> 0 | O14: =IF(OR($A14="",$H14="",Config!$B$4=0),"",$H14/Config!$B$4) | P14: =IF($A14="","",SUM($H$4:$H14)) -> 0 | Q14: =IF($A14="","",IFERROR((AVERAGE($O$4:$O14)-Config!$B$7/Config!$B$6)/STDEV($O$4:$O14)*SQRT(Config!$B$6),"")) | R14: =IF($A14="","",IFERROR((AVERAGE($O$4:$O14)-Config!$B$7/Config!$B$6)/STDEV($O$4:$O14)*SQRT(Config!$B$6),"")) | S14: =IF($H14="",$S13,IF($H14>0,$S13+1,0)) -> 0 | T14: =IF($H14="",$T13,IF($H14<0,$T13+1,0)) -> 0
A15: =IF($A14="","",$A14+1) -> 46246 | B15: =IF($A15="","",TEXT($A15,"ddd")) -> Wed | C15: =IF($A15="","",COUNTIFS('Trade Log'!$L$4:$L$503,$A15)) -> 0 | D15: =IF($A15="","",SUMIFS('Trade Log'!$Q$4:$Q$503,'Trade Log'!$L$4:$L$503,$A15,'Trade Log'!$E$4:$E$503,"LONG")) -> 0 | E15: =IF($A15="","",SUMIFS('Trade Log'!$Q$4:$Q$503,'Trade Log'!$L$4:$L$503,$A15,'Trade Log'!$E$4:$E$503,"SHORT")) -> 0 | F15: =IF($A15="","",$D15+$E15) -> 0 | G15: =IF($A15="","",SUMIFS('Trade Log'!$Y$4:$Y$503,'Trade Log'!$L$4:$L$503,$A15)) -> 0 | H15: =IF($A15="","",IF($C15=0,"",$F15-$G15)) | I15: =IF($A15="","",$I14+IF($H15="",0,$H15)) -> 0 | J15: =IF($A15="","",Config!$B$4+$I15) -> 1000000 | K15: =IF($A15="","",MAX($J$4:$J15)) -> 1000000 | L15: =IF($A15="","",$J15-$K15) -> 0 | M15: =IF(OR($A15="",$K15=0),"",$L15/$K15) -> 0 | N15: =IF($A15="","",SUMIFS('Trade Log'!$K$4:$K$503,'Trade Log'!$H$4:$H$503,$A15)) -> 0 | O15: =IF(OR($A15="",$H15="",Config!$B$4=0),"",$H15/Config!$B$4) | P15: =IF($A15="","",SUM($H$4:$H15)) -> 0 | Q15: =IF($A15="","",IFERROR((AVERAGE($O$4:$O15)-Config!$B$7/Config!$B$6)/STDEV($O$4:$O15)*SQRT(Config!$B$6),"")) | R15: =IF($A15="","",IFERROR((AVERAGE($O$4:$O15)-Config!$B$7/Config!$B$6)/STDEV($O$4:$O15)*SQRT(Config!$B$6),"")) | S15: =IF($H15="",$S14,IF($H15>0,$S14+1,0)) -> 0 | T15: =IF($H15="",$T14,IF($H15<0,$T14+1,0)) -> 0
A16: =IF($A15="","",$A15+1) -> 46247 | B16: =IF($A16="","",TEXT($A16,"ddd")) -> Thu | C16: =IF($A16="","",COUNTIFS('Trade Log'!$L$4:$L$503,$A16)) -> 0 | D16: =IF($A16="","",SUMIFS('Trade Log'!$Q$4:$Q$503,'Trade Log'!$L$4:$L$503,$A16,'Trade Log'!$E$4:$E$503,"LONG")) -> 0 | E16: =IF($A16="","",SUMIFS('Trade Log'!$Q$4:$Q$503,'Trade Log'!$L$4:$L$503,$A16,'Trade Log'!$E$4:$E$503,"SHORT")) -> 0 | F16: =IF($A16="","",$D16+$E16) -> 0 | G16: =IF($A16="","",SUMIFS('Trade Log'!$Y$4:$Y$503,'Trade Log'!$L$4:$L$503,$A16)) -> 0 | H16: =IF($A16="","",IF($C16=0,"",$F16-$G16)) | I16: =IF($A16="","",$I15+IF($H16="",0,$H16)) -> 0 | J16: =IF($A16="","",Config!$B$4+$I16) -> 1000000 | K16: =IF($A16="","",MAX($J$4:$J16)) -> 1000000 | L16: =IF($A16="","",$J16-$K16) -> 0 | M16: =IF(OR($A16="",$K16=0),"",$L16/$K16) -> 0 | N16: =IF($A16="","",SUMIFS('Trade Log'!$K$4:$K$503,'Trade Log'!$H$4:$H$503,$A16)) -> 0 | O16: =IF(OR($A16="",$H16="",Config!$B$4=0),"",$H16/Config!$B$4) | P16: =IF($A16="","",SUM($H$4:$H16)) -> 0 | Q16: =IF($A16="","",IFERROR((AVERAGE($O$4:$O16)-Config!$B$7/Config!$B$6)/STDEV($O$4:$O16)*SQRT(Config!$B$6),"")) | R16: =IF($A16="","",IFERROR((AVERAGE($O$4:$O16)-Config!$B$7/Config!$B$6)/STDEV($O$4:$O16)*SQRT(Config!$B$6),"")) | S16: =IF($H16="",$S15,IF($H16>0,$S15+1,0)) -> 0 | T16: =IF($H16="",$T15,IF($H16<0,$T15+1,0)) -> 0
... A23: =IF($A22="","",$A22+1) -> 46254 | B23: =IF($A23="","",TEXT($A23,"ddd")) -> Thu | C23: =IF($A23="","",COUNTIFS('Trade Log'!$L$4:$L$503,$A23)) -> 0 | D23: =IF($A23="","",SUMIFS('Trade Log'!$Q$4:$Q$503,'Trade Log'!$L$4:$L$503,$A23,'Trade Log'!$E$4:$E$503,"LONG")) -> 0 | E23: =IF($A23="","",SUMIFS('Trade Log'!$Q$4:$Q$503,'Trade Log'!$L$4:$L$503,$A23,'Trade Log'!$E$4:$E$503,"SHORT")) -> 0 | F23: =IF($A23="","",$D23+$E23) -> 0 | G23: =IF($A23="","",SUMIFS('Trade Log'!$Y$4:$Y$503,'Trade Log'!$L$4:$L$503,$A23)) -> 0 | H23: =IF($A23="","",IF($C23=0,"",$F23-$G23)) | I23: =IF($A23="","",$I22+IF($H23="",0,$H23)) -> 23918.552 | J23: =IF($A23="","",Config!$B$4+$I23) -> 1023918.6 | K23: =IF($A23="","",MAX($J$4:$J23)) -> 1023918.6 | L23: =IF($A23="","",$J23-$K23) -> 0 | M23: =IF(OR($A23="",$K23=0),"",$L23/$K23) -> 0 | N23: =IF($A23="","",SUMIFS('Trade Log'!$K$4:$K$503,'Trade Log'!$H$4:$H$503,$A23)) -> 0 | O23: =IF(OR($A23="",$H23="",Config!$B$4=0),"",$H23/Config!$B$4) | P23: =IF($A23="","",SUM($H$4:$H23)) -> 23918.552 | Q23: =IF($A23="","",IFERROR((AVERAGE($O$4:$O23)-Config!$B$7/Config!$B$6)/STDEV($O$4:$O23)*SQRT(Config!$B$6),"")) | R23: =IF($A23="","",IFERROR((AVERAGE($O$4:$O23)-Config!$B$7/Config!$B$6)/STDEV($O$4:$O23)*SQRT(Config!$B$6),"")) | S23: =IF($H23="",$S22,IF($H23>0,$S22+1,0)) -> 1 | T23: =IF($H23="",$T22,IF($H23<0,$T22+1,0)) -> 0
A24: =IF($A23="","",$A23+1) -> 46255 | B24: =IF($A24="","",TEXT($A24,"ddd")) -> Fri | C24: =IF($A24="","",COUNTIFS('Trade Log'!$L$4:$L$503,$A24)) -> 0 | D24: =IF($A24="","",SUMIFS('Trade Log'!$Q$4:$Q$503,'Trade Log'!$L$4:$L$503,$A24,'Trade Log'!$E$4:$E$503,"LONG")) -> 0 | E24: =IF($A24="","",SUMIFS('Trade Log'!$Q$4:$Q$503,'Trade Log'!$L$4:$L$503,$A24,'Trade Log'!$E$4:$E$503,"SHORT")) -> 0 | F24: =IF($A24="","",$D24+$E24) -> 0 | G24: =IF($A24="","",SUMIFS('Trade Log'!$Y$4:$Y$503,'Trade Log'!$L$4:$L$503,$A24)) -> 0 | H24: =IF($A24="","",IF($C24=0,"",$F24-$G24)) | I24: =IF($A24="","",$I23+IF($H24="",0,$H24)) -> 23918.552 | J24: =IF($A24="","",Config!$B$4+$I24) -> 1023918.6 | K24: =IF($A24="","",MAX($J$4:$J24)) -> 1023918.6 | L24: =IF($A24="","",$J24-$K24) -> 0 | M24: =IF(OR($A24="",$K24=0),"",$L24/$K24) -> 0 | N24: =IF($A24="","",SUMIFS('Trade Log'!$K$4:$K$503,'Trade Log'!$H$4:$H$503,$A24)) -> 0 | O24: =IF(OR($A24="",$H24="",Config!$B$4=0),"",$H24/Config!$B$4) | P24: =IF($A24="","",SUM($H$5:$H24)) -> 23918.552 | Q24: =IF($A24="","",IFERROR((AVERAGE($O$5:$O24)-Config!$B$7/Config!$B$6)/STDEV($O$5:$O24)*SQRT(Config!$B$6),"")) | R24: =IF($A24="","",IFERROR((AVERAGE($O$4:$O24)-Config!$B$7/Config!$B$6)/STDEV($O$4:$O24)*SQRT(Config!$B$6),"")) | S24: =IF($H24="",$S23,IF($H24>0,$S23+1,0)) -> 1 | T24: =IF($H24="",$T23,IF($H24<0,$T23+1,0)) -> 0
A25: =IF($A24="","",$A24+1) -> 46256 | B25: =IF($A25="","",TEXT($A25,"ddd")) -> Sat | C25: =IF($A25="","",COUNTIFS('Trade Log'!$L$4:$L$503,$A25)) -> 0 | D25: =IF($A25="","",SUMIFS('Trade Log'!$Q$4:$Q$503,'Trade Log'!$L$4:$L$503,$A25,'Trade Log'!$E$4:$E$503,"LONG")) -> 0 | E25: =IF($A25="","",SUMIFS('Trade Log'!$Q$4:$Q$503,'Trade Log'!$L$4:$L$503,$A25,'Trade Log'!$E$4:$E$503,"SHORT")) -> 0 | F25: =IF($A25="","",$D25+$E25) -> 0 | G25: =IF($A25="","",SUMIFS('Trade Log'!$Y$4:$Y$503,'Trade Log'!$L$4:$L$503,$A25)) -> 0 | H25: =IF($A25="","",IF($C25=0,"",$F25-$G25)) | I25: =IF($A25="","",$I24+IF($H25="",0,$H25)) -> 23918.552 | J25: =IF($A25="","",Config!$B$4+$I25) -> 1023918.6 | K25: =IF($A25="","",MAX($J$4:$J25)) -> 1023918.6 | L25: =IF($A25="","",$J25-$K25) -> 0 | M25: =IF(OR($A25="",$K25=0),"",$L25/$K25) -> 0 | N25: =IF($A25="","",SUMIFS('Trade Log'!$K$4:$K$503,'Trade Log'!$H$4:$H$503,$A25)) -> 0 | O25: =IF(OR($A25="",$H25="",Config!$B$4=0),"",$H25/Config!$B$4) | P25: =IF($A25="","",SUM($H$6:$H25)) -> 23918.552 | Q25: =IF($A25="","",IFERROR((AVERAGE($O$6:$O25)-Config!$B$7/Config!$B$6)/STDEV($O$6:$O25)*SQRT(Config!$B$6),"")) | R25: =IF($A25="","",IFERROR((AVERAGE($O$4:$O25)-Config!$B$7/Config!$B$6)/STDEV($O$4:$O25)*SQRT(Config!$B$6),"")) | S25: =IF($H25="",$S24,IF($H25>0,$S24+1,0)) -> 1 | T25: =IF($H25="",$T24,IF($H25<0,$T24+1,0)) -> 0
